Workbook

Sheet A
B4: TP 10, 11 Y 12
B6: VALUACIÓN DE EMPRESAS - MODELO DCF
B9: Alumno | C9: Luca Camus
B10: Empresa | C10: Agrometal
B11: Ticker | C11: AGRO

Sheet Base
A4: Fecha | B4: MEP diario | D4: Fecha | E4: MEP | G4: Etiquetas de fila | H4: Promedio de MEP | K4: Fecha | L4: Merval | N4: Fecha | O4: Riesgo país | T4: IPC mensual base 2016 | U4: Inflación mensual | V4: Inflacion interanual | W4: Inflación promedio | Z4: Fecha | AA4: EMAE base 2004 s.e | AD4: Fecha | AE4: PBI cte a pesos 2004
A5: 45813 | B5: 1192.38 | D5: 45814 | E5: 1192.4 | G5: 2020 | H5: 122.63622 | K5: 45814 | L5: 2156778.5 | N5: 45814 | O5: 688 | S5: 43831 | T5: 289.8299 | V5: 0.529 | Z5: 43831 | AA5: 140.70852 | AD5: 43922 | AE5: 632389.35 | AH5: Etiquetas de fila | AI5: Promedio de PBI cte a pesos 2004
A6: 45812 | B6: 1193.22 | D6: 45813 | E6: 1192.38 | G6: 2021 | H6: 164.48068 | K6: 45813 | L6: 2124156 | N6: 45813 | O6: 688 | S6: 43862 | T6: 295.666 | U6: =T6/T5-1 -> 0.020136294 | V6: 0.503 | Z6: 43862 | AA6: 138.88807 | AD6: 44013 | AE6: 609379.99 | AH6: 2020 | AI6: 624591.29
A7: 45811 | B7: 1189.67 | D7: 45812 | E7: 1193.22 | G7: 2022 | H7: 250.58223 | K7: 45812 | L7: 2126915.2 | N7: 45812 | O7: 688 | S7: 43891 | T7: 305.5515 | U7: =T7/T6-1 -> 0.033434686 | V7: 0.484 | Z7: 43891 | AA7: 125.48317 | AD7: 44105 | AE7: 614192.48 | AH7: 2021 | AI7: 689809.93
A8: 45810 | B8: 1183.78 | D8: 45811 | E8: 1189.67 | G8: 2023 | H8: 573.54615 | K8: 45811 | L8: 2224638 | N8: 45811 | O8: 668 | S8: 43922 | T8: 310.1243 | U8: =T8/T7-1 -> 0.014965726 | V8: 0.456 | Z8: 43922 | AA8: 106.10837 | AD8: 44166 | AE8: 642403.32 | AH8: 2022 | AI8: 726162.09
A9: 45807 | B9: 1191.72 | D9: 45810 | E9: 1183.78 | G9: 2024 | H9: 1163.4084 | K9: 45810 | L9: 2206291.2 | N9: 45806 | O9: 663 | S9: 43952 | T9: 314.9087 | U9: =T9/T8-1 -> 0.015427363 | V9: 0.434 | Z9: 43952 | AA9: 117.63514 | AD9: 44287 | AE9: 652831.98 | AF9: =AE9/AE5-1 -> 0.032326008 | AH9: 2023 | AI9: 714463.6
A10: 45806 | B10: 1181.9 | D10: 45807 | E10: 1191.72 | G10: 2025 | H10: 1204.6832 | K10: 45807 | L10: 2278991.5 | N10: 45805 | O10: 655 | S10: 43983 | T10: 321.9738 | U10: =T10/T9-1 -> 0.022435392 | V10: 0.428 | Z10: 43983 | AA10: 124.84622 | AD10: 44378 | AE10: 723516.62 | AF10: =AE10/AE6-1 -> 0.18729961 | AH10: 2024 | AI10: 702181.22
A11: 45805 | B11: 1164.8 | D11: 45806 | E11: 1181.9 | G11: Total general | H11: 480.71848 | K11: 45806 | L11: 2308055.8 | N11: 45804 | O11: 666 | S11: 44013 | T11: 328.2014 | U11: =T11/T10-1 -> 0.019341946 | V11: 0.424 | Z11: 44013 | AA11: 126.19018 | AD11: 44470 | AE11: 686756.47 | AF11: =AE11/AE7-1 -> 0.11814536 | AH11: Total general | AI11: 691441.63
A12: 45804 | B12: 1161.3 | D12: 45805 | E12: 1164.8 | K12: 45805 | L12: 2344329.5 | N12: 45803 | O12: 666 | S12: 44044 | T12: 337.0632 | U12: =T12/T11-1 -> 0.027001104 | V12: 0.407 | Z12: 44044 | AA12: 129.01079 | AD12: 44531 | AE12: 696134.67 | AF12: =AE12/AE8-1 -> 0.083641139
A13: 45803 | B13: 1145.42 | D13: 45804 | E13: 1161.3 | K13: 45804 | L13: 2355098.2 | N13: 45800 | O13: 665 | S13: 44075 | T13: 346.6207 | U13: =T13/T12-1 -> 0.028355216 | V13: 0.366 | Z13: 44075 | AA13: 130.82176 | AD13: 44652 | AE13: 697592.04 | AF13: =AE13/AE9-1 -> 0.068562913
A14: 45800 | B14: 1143.32 | D14: 45803 | E14: 1145.42 | K14: 45803 | L14: 2370800 | N14: 45799 | O14: 665 | S14: 44105 | T14: 359.657 | U14: =T14/T13-1 -> 0.037609698 | V14: 0.372 | Z14: 44105 | AA14: 133.64962 | AD14: 44743 | AE14: 774238.21 | AF14: =AE14/AE10-1 -> 0.07010424 | AH14: 2020 | AI14: 624591.29 | AJ14: -0.099
A15: 45799 | B15: 1143.49 | D15: 45800 | E15: 1143.32 | K15: 45800 | L15: 2345902.2 | N15: 45798 | O15: 661 | S15: 44136 | T15: 371.0211 | U15: =T15/T14-1 -> 0.031597049 | V15: 0.358 | Z15: 44136 | AA15: 134.91069 | AD15: 44835 | AE15: 727933.42 | AF15: =AE15/AE11-1 -> 0.059958599 | AH15: 2021 | AI15: 689809.93 | AJ15: =AI15/AI14-1 -> 0.10441812
A16: 45798 | B16: 1148.8 | D16: 45799 | E16: 1143.49 | K16: 45799 | L16: 2314897 | N16: 45797 | O16: 663 | S16: 44166 | T16: 385.8826 | U16: =T16/T15-1 -> 0.040055673 | V16: 0.361 | Z16: 44166 | AA16: 136.76102 | AD16: 44896 | AE16: 704884.68 | AF16: =AE16/AE12-1 -> 0.012569426 | AH16: 2022 | AI16: 726162.09 | AJ16: =AI16/AI15-1 -> 0.052698797
A17: 45797 | B17: 1153.33 | D17: 45798 | E17: 1148.8 | K17: 45798 | L17: 2319548.5 | N17: 45796 | O17: 675 | S17: 44197 | T17: 401.5071 | U17: =T17/T16-1 -> 0.040490294 | V17: =T17/T5-1 -> 0.3853198 | Z17: 44197 | AA17: 139.73714 | AD17: 45017 | AE17: 705021.1 | AF17: =AE17/AE13-1 -> 0.010649574 | AH17: 2023 | AI17: 714463.6 | AJ17: =AI17/AI16-1 -> -0.016110016
A18: 45796 | B18: 1148.77 | D18: 45797 | E18: 1153.33 | K18: 45797 | L18: 2378464 | N18: 45793 | O18: 676 | S18: 44228 | T18: 415.8595 | U18: =T18/T17-1 -> 0.035746317 | V18: =T18/T6-1 -> 0.40651783 | Z18: 44228 | AA18: 137.25835 | AD18: 45108 | AE18: 733350.47 | AF18: =AE18/AE14-1 -> -0.052810274 | AH18: 2024 | AI18: 702181.22 | AJ18: =AI18/AI17-1 -> -0.017191052
A19: 45793 | B19: 1155.12 | D19: 45796 | E19: 1148.77 | K19: 45796 | L19: 2369505.2 | N19: 45792 | O19: 676 | S19: 44256 | T19: 435.8657 | U19: =T19/T18-1 -> 0.048108075 | V19: =T19/T7-1 -> 0.4264885 | Z19: 44256 | AA19: 140.61116 | AD19: 45200 | AE19: 723190.59 | AF19: =AE19/AE15-1 -> -0.006515474 | AH19: 2025 | AJ19: 0.055
A20: 45792 | B20: 1140.92 | D20: 45793 | E20: 1155.12 | K20: 45793 | L20: 2318360 | N20: 45791 | O20: 648 | S20: 44287 | T20: 453.6503 | U20: =T20/T19-1 -> 0.040802935 | V20: =T20/T8-1 -> 0.46280153 | Z20: 44287 | AA20: 139.63372 | AD20: 45261 | AE20: 696292.25 | AF20: =AE20/AE16-1 -> -0.012189834 | AH20: 2026 | AJ20: 0.045
A21: 45791 | B21: 1140.92 | D21: 45792 | E21: 1140.92 | K21: 45792 | L21: 2298473 | N21: 45790 | O21: 651 | S21: 44317 | T21: 468.725 | U21: =T21/T20-1 -> 0.033229781 | V21: =T21/T9-1 -> 0.48844729 | Z21: 44317 | AA21: 139.10437 | AD21: 45383 | AE21: 668672.71 | AF21: =AE21/AE17-1 -> -0.051556447 | AH21: 2027 | AJ21: 0.04
A22: 45790 | B22: 1140.92 | D22: 45791 | E22: 1140.92 | K22: 45791 | L22: 2301643.2 | N22: 45789 | O22: 650 | S22: 44348 | T22: 483.6049 | U22: =T22/T21-1 -> 0.03174548 | V22: =T22/T10-1 -> 0.50200078 | Z22: 44348 | AA22: 141.74208 | AD22: 45474 | AE22: 720760.48 | AF22: =AE22/AE18-1 -> -0.017167772 | AH22: 2028 | AJ22: 0.032
A23: 45789 | B23: 1141.2 | D23: 45790 | E23: 1140.92 | K23: 45790 | L23: 2285483.2 | N23: 45786 | O23: 678 | S23: 44378 | T23: 498.0987 | U23: =T23/T22-1 -> 0.029970333 | V23: =T23/T11-1 -> 0.51766172 | Z23: 44378 | AA23: 141.54961 | AD23: 45566 | AE23: 708557 | AF23: =AE23/AE19-1 -> -0.020234764 | AH23: 2029 | AJ23: 0.031
A24: 45786 | B24: 1144.11 | D24: 45789 | E24: 1141.2 | K24: 45789 | L24: 2230394.8 | N24: 45785 | O24: 678 | S24: 44409 | T24: 510.3942 | U24: =T24/T23-1 -> 0.024684867 | V24: =T24/T12-1 -> 0.51423887 | Z24: 44409 | AA24: 143.43631 | AD24: 45627 | AE24: 710734.7 | AF24: =AE24/AE20-1 -> 0.02074193 | AH24: 2030 | AJ24: 0.03
A25: 45785 | B25: 1143.32 | D25: 45786 | E25: 1144.11 | K25: 45786 | L25: 2114385.5 | N25: 45784 | O25: 766 | S25: 44440 | T25: 528.4968 | U25: =T25/T24-1 -> 0.03546788 | V25: =T25/T13-1 -> 0.52471217 | Z25: 44440 | AA25: 144.04418
A26: 45784 | B26: 1156.07 | D26: 45785 | E26: 1143.32 | K26: 45785 | L26: 2061722.2 | N26: 45783 | O26: 741 | S26: 44470 | T26: 547.0802 | U26: =T26/T25-1 -> 0.035162748 | V26: =T26/T14-1 -> 0.52111651 | Z26: 44470 | AA26: 143.53112
A27: 45783 | B27: 1199.61 | D27: 45784 | E27: 1156.07 | K27: 45784 | L27: 2059914.9 | N27: 45782 | O27: 741 | S27: 44501 | T27: 560.9184 | U27: =T27/T26-1 -> 0.025294646 | V27: =T27/T15-1 -> 0.51182345 | Z27: 44501 | AA27: 145.86834
A28: 45782 | B28: 1202.92 | D28: 45783 | E28: 1199.61 | K28: 45783 | L28: 2129994.5 | N28: 45779 | O28: 741 | S28: 44531 | T28: 582.4575 | U28: =T28/T27-1 -> 0.038399703 | V28: =T28/T16-1 -> 0.50941634 | Z28: 44531 | AA28: 149.82457
A29: 45779 | B29: 1183.37 | D29: 45782 | E29: 1202.92 | K29: 45782 | L29: 2059931.6 | N29: 45778 | O29: 735 | S29: 44562 | T29: 605.0317 | U29: =T29/T28-1 -> 0.038756819 | V29: =T29/T17-1 -> 0.50690162 | Z29: 44562 | AA29: 148.19264
A30: 45778 | B30: 1183.37 | D30: 45779 | E30: 1183.37 | K30: 45777 | L30: 2100843.8 | N30: 45777 | O30: 726 | S30: 44593 | T30: 633.4341 | U30: =T30/T29-1 -> 0.046943656 | V30: =T30/T18-1 -> 0.52319257 | Z30: 44593 | AA30: 149.89959
A31: 45777 | B31: 1183.37 | D31: 45778 | E31: 1183.37 | K31: 45776 | L31: 2158847.8 | N31: 45776 | O31: 701 | S31: 44621 | T31: 676.0566 | U31: =T31/T30-1 -> 0.067287978 | V31: =T31/T19-1 -> 0.5510663 | Z31: 44621 | AA31: 149.58
A32: 45776 | B32: 1173.15 | D32: 45777 | E32: 1183.37 | K32: 45775 | L32: 2179248.8 | N32: 45775 | O32: 710 | S32: 44652 | T32: 716.9399 | U32: =T32/T31-1 -> 0.060473191 | V32: =T32/T20-1 -> 0.58038009 | Z32: 44652 | AA32: 150.80114
A33: 45775 | B33: 1176.55 | D33: 45776 | E33: 1173.15 | K33: 45772 | L33: 2225242.8 | N33: 45772 | O33: 692 | S33: 44682 | T33: 753.147 | U33: =T33/T32-1 -> 0.050502281 | V33: =T33/T21-1 -> 0.6067993 | Z33: 44682 | AA33: 150.93255
A34: 45772 | B34: 1184.24 | D34: 45775 | E34: 1176.55 | K34: 45771 | L34: 2232745.2 | N34: 45771 | O34: 713 | S34: 44713 | T34: 793.0278 | U34: =T34/T33-1 -> 0.052952213 | V34: =T34/T22-1 -> 0.63982582 | Z34: 44713 | AA34: 152.48435
A35: 45771 | B35: 1186.53 | D35: 45772 | E35: 1184.24 | K35: 45770 | L35: 2239402 | N35: 45770 | O35: 720 | S35: 44743 | T35: 851.761 | U35: =T35/T34-1 -> 0.074061969 | V35: =T35/T23-1 -> 0.71002454 | Z35: 44743 | AA35: 151.4232
A36: 45770 | B36: 1168 | D36: 45771 | E36: 1186.53 | K36: 45769 | L36: 2163891 | N36: 45769 | O36: 720 | S36: 44774 | T36: 911.1316 | U36: =T36/T35-1 -> 0.069703356 | V36: =T36/T24-1 -> 0.78515273 | Z36: 44774 | AA36: 150.86399
... A67: 45727 | B67: 1230.38 | D67: 45728 | E67: 1229.34 | K67: 45716 | L67: 2205800.5 | N67: 45723 | O67: 692 | S67: 45717 | T67: 8353.3158 | U67: =T67/T66-1 -> 0.037293353 | V67: =T67/T55-1 -> 0.55930016 | Z67: 45717 | AA67: 149.89801
A68: 45726 | B68: 1228.92 | D68: 45727 | E68: 1230.38 | K68: 45715 | L68: 2193656.8 | N68: 45722 | O68: 714 | S68: 45748 | T68: 8585.6078 | U68: =T68/T67-1 -> 0.027808358 | V68: =T68/T56-1 -> 0.47260264 | Z68: 45748
A69: 45723 | B69: 1221.93 | D69: 45726 | E69: 1228.92 | K69: 45714 | L69: 2275036.8 | N69: 45721 | O69: 717
A70: 45722 | B70: 1237.86 | D70: 45723 | E70: 1221.93 | K70: 45713 | L70: 2282898.8 | N70: 45720 | O70: 780
A71: 45721 | B71: 1235.31 | D71: 45722 | E71: 1237.86 | K71: 45712 | L71: 2348398.5 | N71: 45719 | O71: 780
A72: 45720 | B72: 1228.48 | D72: 45721 | E72: 1235.31 | K72: 45709 | L72: 2364529.5 | N72: 45716 | O72: 780
A73: 45719 | B73: 1228.48 | D73: 45720 | E73: 1228.48 | K73: 45708 | L73: 2410221 | N73: 45715 | O73: 769
...

Sheet 1) Estadística
A9: Fecha | B9: AGRO $ | C9: Merval $ | D9: Rend AGRO | E9: Rend Merval | F9: MEP | G9: AGRO USD | H9: Merval USD | I9: Rend AGRO2 | J9: Rend Merval3 | K9: Riesgo país
A10: 45814 | B10: 48.2 | C10: =VLOOKUP(Tabla1[[#This Row],[Fecha]],[1]Base!$K$5:$L$249,2,FALSE) -> 2156778.5 | D10: =LN(B10/B11) -> 0.0093799541 | E10: =LN(C10/C11) -> 0.015241126 | F10: 1192.4 | G10: =B10/F10 -> 0.040422677 | H10: =Tabla1[[#This Row],[Merval $]]/F10 -> 1808.771 | I10: =LN(G10/G11) -> 0.0093631811 | J10: =LN(H10/H11) -> 0.015224353 | K10: =VLOOKUP(Tabla1[[#This Row],[Fecha]],[1]Base!$N$5:$O$263,2,FALSE) -> 688
A11: 45813 | B11: 47.75 | C11: =VLOOKUP(Tabla1[[#This Row],[Fecha]],[1]Base!$K$5:$L$249,2,FALSE) -> 2124156 | D11: =LN(B11/B12) -> -0.025841231 | E11: =LN(C11/C12) -> -0.0012981436 | F11: =VLOOKUP(A11,[1]Base!$A$5:$B$265, 2, FALSE) -> 1192.38 | G11: =B11/F11 -> 0.040045959 | H11: =Tabla1[[#This Row],[Merval $]]/F11 -> 1781.4422 | I11: =LN(G11/G12) -> -0.025137006 | J11: =LN(H11/H12) -> -0.00059391818 | K11: =VLOOKUP(Tabla1[[#This Row],[Fecha]],[1]Base!$N$5:$O$263,2,FALSE) -> 688
A12: 45812 | B12: 49 | C12: =VLOOKUP(Tabla1[[#This Row],[Fecha]],[1]Base!$K$5:$L$249,2,FALSE) -> 2126915.2 | D12: =LN(B12/B13) -> -0.055569851 | E12: =LN(C12/C13) -> -0.044921515 | F12: =VLOOKUP(A12,[1]Base!$A$5:$B$265, 2, FALSE) -> 1193.22 | G12: =B12/F12 -> 0.041065353 | H12: =Tabla1[[#This Row],[Merval $]]/F12 -> 1782.5005 | I12: =LN(G12/G13) -> -0.058549429 | J12: =LN(H12/H13) -> -0.047901093 | K12: =VLOOKUP(Tabla1[[#This Row],[Fecha]],[1]Base!$N$5:$O$263,2,FALSE) -> 688
A13: 45811 | B13: 51.8 | C13: =VLOOKUP(Tabla1[[#This Row],[Fecha]],[1]Base!$K$5:$L$249,2,FALSE) -> 2224638 | D13: =LN(B13/B14) -> 0.053531114 | E13: =LN(C13/C14) -> 0.0082812673 | F13: =VLOOKUP(A13,[1]Base!$A$5:$B$265, 2, FALSE) -> 1189.67 | G13: =B13/F13 -> 0.043541486 | H13: =Tabla1[[#This Row],[Merval $]]/F13 -> 1869.9623 | I13: =LN(G13/G14) -> 0.048567865 | J13: =LN(H13/H14) -> 0.003318018 | K13: =VLOOKUP(Tabla1[[#This Row],[Fecha]],[1]Base!$N$5:$O$263,2,FALSE) -> 668
A14: 45810 | B14: 49.1 | C14: =VLOOKUP(Tabla1[[#This Row],[Fecha]],[1]Base!$K$5:$L$249,2,FALSE) -> 2206291.2 | D14: =LN(B14/B15) -> -0.045779138 | E14: =LN(C14/C15) -> -0.032420082 | F14: =VLOOKUP(A14,[1]Base!$A$5:$B$265, 2, FALSE) -> 1183.78 | G14: =B14/F14 -> 0.041477302 | H14: =Tabla1[[#This Row],[Merval $]]/F14 -> 1863.768 | I14: =LN(G14/G15) -> -0.039094204 | J14: =LN(H14/H15) -> -0.025735149 | K14: =VLOOKUP(Tabla1[[#This Row],[Fecha]],[1]Base!$N$5:$O$263,2,FALSE) -> #N/A
A15: 45807 | B15: 51.4 | C15: =VLOOKUP(Tabla1[[#This Row],[Fecha]],[1]Base!$K$5:$L$249,2,FALSE) -> 2278991.5 | D15: =LN(B15/B16) -> -0.038172574 | E15: =LN(C15/C16) -> -0.012672483 | F15: =VLOOKUP(A15,[1]Base!$A$5:$B$265, 2, FALSE) -> 1191.72 | G15: =B15/F15 -> 0.043130937 | H15: =Tabla1[[#This Row],[Merval $]]/F15 -> 1912.3548 | I15: =LN(G15/G16) -> -0.046446902 | J15: =LN(H15/H16) -> -0.020946812 | K15: =VLOOKUP(Tabla1[[#This Row],[Fecha]],[1]Base!$N$5:$O$263,2,FALSE) -> #N/A
A16: 45806 | B16: 53.4 | C16: =VLOOKUP(Tabla1[[#This Row],[Fecha]],[1]Base!$K$5:$L$249,2,FALSE) -> 2308055.8 | D16: =LN(B16/B17) -> 0 | E16: =LN(C16/C17) -> -0.01559393 | F16: =VLOOKUP(A16,[1]Base!$A$5:$B$265, 2, FALSE) -> 1181.9 | G16: =B16/F16 -> 0.045181487 | H16: =Tabla1[[#This Row],[Merval $]]/F16 -> 1952.8351 | I16: =LN(G16/G17) -> -0.014573915 | J16: =LN(H16/H17) -> -0.030167845 | K16: =VLOOKUP(Tabla1[[#This Row],[Fecha]],[1]Base!$N$5:$O$263,2,FALSE) -> 663
A17: 45805 | B17: 53.4 | C17: =VLOOKUP(Tabla1[[#This Row],[Fecha]],[1]Base!$K$5:$L$249,2,FALSE) -> 2344329.5 | D17: =LN(B17/B18) -> -0.0018709079 | E17: =LN(C17/C18) -> -0.0045830128 | F17: =VLOOKUP(A17,[1]Base!$A$5:$B$265, 2, FALSE) -> 1164.8 | G17: =B17/F17 -> 0.04584478 | H17: =Tabla1[[#This Row],[Merval $]]/F17 -> 2012.6455 | I17: =LN(G17/G18) -> -0.0048802391 | J17: =LN(H17/H18) -> -0.007592344 | K17: =VLOOKUP(Tabla1[[#This Row],[Fecha]],[1]Base!$N$5:$O$263,2,FALSE) -> 655
A18: 45804 | B18: 53.5 | C18: =VLOOKUP(Tabla1[[#This Row],[Fecha]],[1]Base!$K$5:$L$249,2,FALSE) -> 2355098.2 | D18: =LN(B18/B19) -> 0.030362864 | E18: =LN(C18/C19) -> -0.0066450046 | F18: =VLOOKUP(A18,[1]Base!$A$5:$B$265, 2, FALSE) -> 1161.3 | G18: =B18/F18 -> 0.046069061 | H18: =Tabla1[[#This Row],[Merval $]]/F18 -> 2027.9844 | I18: =LN(G18/G19) -> 0.016594178 | J18: =LN(H18/H19) -> -0.02041369 | K18: =VLOOKUP(Tabla1[[#This Row],[Fecha]],[1]Base!$N$5:$O$263,2,FALSE) -> 666
A19: 45803 | B19: 51.9 | C19: =VLOOKUP(Tabla1[[#This Row],[Fecha]],[1]Base!$K$5:$L$249,2,FALSE) -> 2370800 | D19: =LN(B19/B20) -> -0.0057637047 | E19: =LN(C19/C20) -> 0.010557368 | F19: =VLOOKUP(A19,[1]Base!$A$5:$B$265, 2, FALSE) -> 1145.42 | G19: =B19/F19 -> 0.04531089 | H19: =Tabla1[[#This Row],[Merval $]]/F19 -> 2069.8085 | I19: =LN(G19/G20) -> -0.0075987761 | J19: =LN(H19/H20) -> 0.0087222969 | K19: =VLOOKUP(Tabla1[[#This Row],[Fecha]],[1]Base!$N$5:$O$263,2,FALSE) -> 666
A20: 45800 | B20: 52.2 | C20: =VLOOKUP(Tabla1[[#This Row],[Fecha]],[1]Base!$K$5:$L$249,2,FALSE) -> 2345902.2 | D20: =LN(B20/B21) -> -0.015209419 | E20: =LN(C20/C21) -> 0.013304889 | F20: =VLOOKUP(A20,[1]Base!$A$5:$B$265, 2, FALSE) -> 1143.32 | G20: =B20/F20 -> 0.045656509 | H20: =Tabla1[[#This Row],[Merval $]]/F20 -> 2051.8335 | I20: =LN(G20/G21) -> -0.01506074 | J20: =LN(H20/H21) -> 0.013453567 | K20: =VLOOKUP(Tabla1[[#This Row],[Fecha]],[1]Base!$N$5:$O$263,2,FALSE) -> 665
A21: 45799 | B21: 53 | C21: =VLOOKUP(Tabla1[[#This Row],[Fecha]],[1]Base!$K$5:$L$249,2,FALSE) -> 2314897 | D21: =LN(B21/B22) -> 0.009478744 | E21: =LN(C21/C22) -> -0.0020073606 | F21: =VLOOKUP(A21,[1]Base!$A$5:$B$265, 2, FALSE) -> 1143.49 | G21: =B21/F21 -> 0.046349334 | H21: =Tabla1[[#This Row],[Merval $]]/F21 -> 2024.4139 | I21: =LN(G21/G22) -> 0.014111674 | J21: =LN(H21/H22) -> 0.0026255694 | K21: =VLOOKUP(Tabla1[[#This Row],[Fecha]],[1]Base!$N$5:$O$263,2,FALSE) -> 665
A22: 45798 | B22: 52.5 | C22: =VLOOKUP(Tabla1[[#This Row],[Fecha]],[1]Base!$K$5:$L$249,2,FALSE) -> 2319548.5 | D22: =LN(B22/B23) -> -0.037387532 | E22: =LN(C22/C23) -> -0.025082347 | F22: =VLOOKUP(A22,[1]Base!$A$5:$B$265, 2, FALSE) -> 1148.8 | G22: =B22/F22 -> 0.045699861 | H22: =Tabla1[[#This Row],[Merval $]]/F22 -> 2019.1056 | I22: =LN(G22/G23) -> -0.033452041 | J22: =LN(H22/H23) -> -0.021146856 | K22: =VLOOKUP(Tabla1[[#This Row],[Fecha]],[1]Base!$N$5:$O$263,2,FALSE) -> 661
... A40: 45770 | B40: 43.45 | C40: =VLOOKUP(Tabla1[[#This Row],[Fecha]],[1]Base!$K$5:$L$249,2,FALSE) -> 2239402 | D40: =LN(B40/B41) -> 0.031563111 | E40: =LN(C40/C41) -> 0.034300876 | F40: =VLOOKUP(A40,[1]Base!$A$5:$B$265, 2, FALSE) -> 1168 | G40: =B40/F40 -> 0.037200342 | H40: =Tabla1[[#This Row],[Merval $]]/F40 -> 1917.2962 | I40: =LN(G40/G41) -> 0.0076317668 | J40: =LN(H40/H41) -> 0.010369532 | K40: =VLOOKUP(Tabla1[[#This Row],[Fecha]],[1]Base!$N$5:$O$263,2,FALSE) -> 720
A41: 45769 | B41: 42.1 | C41: =VLOOKUP(Tabla1[[#This Row],[Fecha]],[1]Base!$K$5:$L$249,2,FALSE) -> 2163891 | D41: =LN(B41/B42) -> -0.019988908 | E41: =LN(C41/C42) -> 0.056164353 | F41: =VLOOKUP(A41,[1]Base!$A$5:$B$265, 2, FALSE) -> 1140.38 | G41: =B41/F41 -> 0.036917519 | H41: =Tabla1[[#This Row],[Merval $]]/F41 -> 1897.5175 | I41: =LN(G41/G42) -> -0.036166342 | J41: =LN(H41/H42) -> 0.039986919 | K41: =VLOOKUP(Tabla1[[#This Row],[Fecha]],[1]Base!$N$5:$O$263,2,FALSE) -> 720 | P41: AGRO | R41: S&P | V41: AGRO
A42: 45768 | B42: 42.95 | C42: =VLOOKUP(Tabla1[[#This Row],[Fecha]],[1]Base!$K$5:$L$249,2,FALSE) -> 2045707.4 | D42: =LN(B42/B43) -> -0.11012215 | E42: =LN(C42/C43) -> -0.062651909 | F42: =VLOOKUP(A42,[1]Base!$A$5:$B$265, 2, FALSE) -> 1122.08 | G42: =B42/F42 -> 0.038277128 | H42: =Tabla1[[#This Row],[Merval $]]/F42 -> 1823.1386 | I42: =LN(G42/G43) -> -0.071787207 | J42: =LN(H42/H43) -> -0.024316963 | K42: =VLOOKUP(Tabla1[[#This Row],[Fecha]],[1]Base!$N$5:$O$263,2,FALSE) -> 720 | P42: $ | Q42: USD | R42: $ | S42: USD | V42: $ | W42: USD
A43: 45763 | B43: 47.95 | C43: =VLOOKUP(Tabla1[[#This Row],[Fecha]],[1]Base!$K$5:$L$249,2,FALSE) -> 2177975 | D43: =LN(B43/B44) -> -0.10765194 | E43: =LN(C43/C44) -> -0.047655111 | F43: =VLOOKUP(A43,[1]Base!$A$5:$B$265, 2, FALSE) -> 1165.93 | G43: =B43/F43 -> 0.041125968 | H43: =Tabla1[[#This Row],[Merval $]]/F43 -> 1868.0152 | I43: =LN(G43/G44) -> -0.047754601 | J43: =LN(H43/H44) -> 0.012242232 | K43: =VLOOKUP(Tabla1[[#This Row],[Fecha]],[1]Base!$N$5:$O$263,2,FALSE) -> 745 | O43: Curtosis | P43: =KURT(Tabla1[Rend AGRO]) -> 1.5011416 | Q43: =KURT(I10:I255) -> 1.5007314 | R43: =KURT(E10:E255) -> 2.3075668 | S43: =KURT(J10:J255) -> 1.6945733 | U43: Min | V43: =INDEX(Tabla1[Fecha],MATCH(MIN(Tabla1[AGRO $]),Tabla1[AGRO $],0)) -> 45782 | W43: =INDEX(Tabla1[Fecha],MATCH(MIN(Tabla1[AGRO USD]),Tabla1[AGRO USD],0)) -> 45757
A44: 45762 | B44: 53.4 | C44: =VLOOKUP(Tabla1[[#This Row],[Fecha]],[1]Base!$K$5:$L$249,2,FALSE) -> 2284279.5 | D44: =LN(B44/B45) -> 0.0037523496 | E44: =LN(C44/C45) -> -0.034706223 | F44: =VLOOKUP(A44,[1]Base!$A$5:$B$265, 2, FALSE) -> 1237.9 | G44: =B44/F44 -> 0.043137572 | H44: =Tabla1[[#This Row],[Merval $]]/F44 -> 1845.286 | I44: =LN(G44/G45) -> 0.016195813 | J44: =LN(H44/H45) -> -0.022262759 | K44: =VLOOKUP(Tabla1[[#This Row],[Fecha]],[1]Base!$N$5:$O$263,2,FALSE) -> 725 | O44: Simetría | P44: =_xlfn.SKEW.P(D10:D254) -> 0.507734 | Q44: =_xlfn.SKEW.P(I10:I254) -> 0.68153452 | R44: =_xlfn.SKEW.P(E10:E254) -> -0.40569141 | S44: =_xlfn.SKEW.P(J10:J254) -> 0.23074705 | U44: Max | V44: =INDEX(Tabla1[Fecha],MATCH(MAX(Tabla1[AGRO $]),Tabla1[AGRO $],0)) -> 45643 | W44: =INDEX(Tabla1[Fecha],MATCH(MAX(Tabla1[AGRO USD]),Tabla1[AGRO USD],0)) -> 45629
A45: 45761 | B45: 53.2 | C45: =VLOOKUP(Tabla1[[#This Row],[Fecha]],[1]Base!$K$5:$L$249,2,FALSE) -> 2364950 | D45: =LN(B45/B46) -> 0.080199362 | E45: =LN(C45/C46) -> 0.050358805 | F45: =VLOOKUP(A45,[1]Base!$A$5:$B$265, 2, FALSE) -> 1253.4 | G45: =B45/F45 -> 0.042444551 | H45: =Tabla1[[#This Row],[Merval $]]/F45 -> 1886.8278 | I45: =LN(G45/G46) -> 0.14201908 | J45: =LN(H45/H46) -> 0.11217852 | K45: =VLOOKUP(Tabla1[[#This Row],[Fecha]],[1]Base!$N$5:$O$263,2,FALSE) -> 896 | O45: Observaciones | P45: =COUNT(D10:D254) -> 245 | Q45: =COUNT(I10:I254) -> 245 | R45: =COUNT(E10:E254) -> 245 | S45: =COUNT(J10:J254) -> 245
A46: 45758 | B46: 49.1 | C46: =VLOOKUP(Tabla1[[#This Row],[Fecha]],[1]Base!$K$5:$L$249,2,FALSE) -> 2248803 | D46: =LN(B46/B47) -> 0.073951318 | E46: =LN(C46/C47) -> 0.063004097 | F46: =VLOOKUP(A46,[1]Base!$A$5:$B$265, 2, FALSE) -> 1333.33 | G46: =B46/F46 -> 0.036825092 | H46: =Tabla1[[#This Row],[Merval $]]/F46 -> 1686.6065 | I46: =LN(G46/G47) -> 0.096700637 | J46: =LN(H46/H47) -> 0.085753415 | K46: =VLOOKUP(Tabla1[[#This Row],[Fecha]],[1]Base!$N$5:$O$263,2,FALSE) -> 874 | O46: Jarque- Bera | P46: =(P45/6)*(P44^2+(P43^2)/4) -> 33.530307 | Q46: =(Q45/6)*(Q44^2+(Q43^2)/4) -> 41.957801 | R46: =(R45/6)*(R44^2+(R43^2)/4) -> 61.078566 | S46: =(S45/6)*(S44^2+(S43^2)/4) -> 31.488169
A47: 45757 | B47: 45.6 | C47: =VLOOKUP(Tabla1[[#This Row],[Fecha]],[1]Base!$K$5:$L$249,2,FALSE) -> 2111490.2 | D47: =LN(B47/B48) -> -0.063715814 | E47: =LN(C47/C48) -> -0.03357038 | F47: =VLOOKUP(A47,[1]Base!$A$5:$B$265, 2, FALSE) -> 1364.01 | G47: =B47/F47 -> 0.03343084 | H47: =Tabla1[[#This Row],[Merval $]]/F47 -> 1548.002 | I47: =LN(G47/G48) -> -0.080192332 | J47: =LN(H47/H48) -> -0.050046898 | K47: =VLOOKUP(Tabla1[[#This Row],[Fecha]],[1]Base!$N$5:$O$263,2,FALSE) -> 899 | O47: p-value | P47: =_xlfn.CHISQ.DIST(P46,2,) -> 2.6179204e-08 | Q47: =_xlfn.CHISQ.DIST(Q46,2,) -> 3.8721237e-10 | R47: =_xlfn.CHISQ.DIST(R46,2,) -> 2.7285243e-14 | S47: =_xlfn.CHISQ.DIST(S46,2,) -> 7.267767e-08
A48: 45756 | B48: 48.6 | C48: =VLOOKUP(Tabla1[[#This Row],[Fecha]],[1]Base!$K$5:$L$249,2,FALSE) -> 2183577 | D48: =LN(B48/B49) -> 0.025001302 | E48: =LN(C48/C49) -> 0.092517582 | F48: =VLOOKUP(A48,[1]Base!$A$5:$B$265, 2, FALSE) -> 1341.72 | G48: =B48/F48 -> 0.036222163 | H48: =Tabla1[[#This Row],[Merval $]]/F48 -> 1627.4461 | I48: =LN(G48/G49) -> 0.050651092 | J48: =LN(H48/H49) -> 0.11816737 | K48: =VLOOKUP(Tabla1[[#This Row],[Fecha]],[1]Base!$N$5:$O$263,2,FALSE) -> 889
A49: 45755 | B49: 47.4 | C49: =VLOOKUP(Tabla1[[#This Row],[Fecha]],[1]Base!$K$5:$L$249,2,FALSE) -> 1990621.2 | D49: =LN(B49/B50) -> 0.015949301 | E49: =LN(C49/C50) -> -0.017600465 | F49: =VLOOKUP(A49,[1]Base!$A$5:$B$265, 2, FALSE) -> 1376.58 | G49: =B49/F49 -> 0.03443316 | H49: =Tabla1[[#This Row],[Merval $]]/F49 -> 1446.0629 | I49: =LN(G49/G50) -> 0.011413321 | J49: =LN(H49/H50) -> -0.022136446 | K49: =VLOOKUP(Tabla1[[#This Row],[Fecha]],[1]Base!$N$5:$O$263,2,FALSE) -> 978 | O49: Rendimiento diario | P49: =AVERAGE(D10:D254) -> -0.00043342876 | Q49: =AVERAGE(I9:I253) -> -0.00032404155 | R49: =AVERAGE(E10:E254) -> 0.0014721145 | S49: =AVERAGE(J10:J254) -> 0.0017359115 | V49: S&P
A50: 45754 | B50: 46.65 | C50: =VLOOKUP(Tabla1[[#This Row],[Fecha]],[1]Base!$K$5:$L$249,2,FALSE) -> 2025967.2 | D50: =LN(B50/B51) -> -0.062325463 | E50: =LN(C50/C51) -> -0.0396051 | F50: =VLOOKUP(A50,[1]Base!$A$5:$B$265, 2, FALSE) -> 1370.35 | G50: =B50/F50 -> 0.034042398 | H50: =Tabla1[[#This Row],[Merval $]]/F50 -> 1478.4305 | I50: =LN(G50/G51) -> -0.084393727 | J50: =LN(H50/H51) -> -0.061673363 | K50: =VLOOKUP(Tabla1[[#This Row],[Fecha]],[1]Base!$N$5:$O$263,2,FALSE) -> 960 | O50: Desviación | P50: =STDEV(D10:D254) -> 0.035781413 | Q50: =STDEV(I10:I254) -> 0.037594211 | R50: =STDEV(E10:E254) -> 0.027062429 | S50: =STDEV(J10:J254) -> 0.029370398 | V50: $ | W50: USD
A51: 45751 | B51: 49.65 | C51: =VLOOKUP(Tabla1[[#This Row],[Fecha]],[1]Base!$K$5:$L$249,2,FALSE) -> 2107816 | D51: =LN(B51/B52) -> -0.057717729 | E51: =LN(C51/C52) -> -0.076617231 | F51: =VLOOKUP(A51,[1]Base!$A$5:$B$265, 2, FALSE) -> 1340.44 | G51: =B51/F51 -> 0.037040076 | H51: =Tabla1[[#This Row],[Merval $]]/F51 -> 1572.4807 | I51: =LN(G51/G52) -> -0.073523401 | J51: =LN(H51/H52) -> -0.092422903 | K51: =VLOOKUP(Tabla1[[#This Row],[Fecha]],[1]Base!$N$5:$O$263,2,FALSE) -> 925 | O51: Min | P51: =MIN(Tabla1[AGRO $]) -> 40.45 | Q51: =MIN(G10:G255) -> 0.03343084 | R51: =MIN(Tabla1[Merval $]) -> 1411953.4 | S51: =MIN(H10:H255) -> 1055.2957 | U51: Min | V51: =INDEX(Tabla1[Fecha],MATCH(MIN(Tabla1[Merval $]),Tabla1[Merval $],0)) -> 45503 | W51: =INDEX(Tabla1[Fecha],MATCH(MIN(Tabla1[Merval USD]),Tabla1[Merval USD],0)) -> 45509
A52: 45750 | B52: 52.6 | C52: =VLOOKUP(Tabla1[[#This Row],[Fecha]],[1]Base!$K$5:$L$249,2,FALSE) -> 2275658.8 | D52: =LN(B52/B53) -> -0.03914759 | E52: =LN(C52/C53) -> -0.034920945 | F52: =VLOOKUP(A52,[1]Base!$A$5:$B$265, 2, FALSE) -> 1319.42 | G52: =B52/F52 -> 0.039866002 | H52: =Tabla1[[#This Row],[Merval $]]/F52 -> 1724.7417 | I52: =LN(G52/G53) -> -0.042906293 | J52: =LN(H52/H53) -> -0.038679649 | K52: =VLOOKUP(Tabla1[[#This Row],[Fecha]],[1]Base!$N$5:$O$263,2,FALSE) -> 872 | O52: Max | P52: =MAX(Tabla1[AGRO $]) -> 84 | Q52: =MAX(G10:G255) -> 0.077534514 | R52: =MAX(Tabla1[Merval $]) -> 2829730.5 | S52: =MAX(H10:H255) -> 2430.6432 | U52: Max | V52: =INDEX(Tabla1[Fecha],MATCH(MAX(Tabla1[Merval $]),Tabla1[Merval $],0)) -> 45666 | W52: =INDEX(Tabla1[Fecha],MATCH(MAX(Tabla1[Merval USD]),Tabla1[Merval USD],0)) -> 45666
A53: 45748 | B53: 54.7 | C53: =VLOOKUP(Tabla1[[#This Row],[Fecha]],[1]Base!$K$5:$L$249,2,FALSE) -> 2356530.8 | D53: =LN(B53/B54) -> -0.0018264845 | E53: =LN(C53/C54) -> 0.0075693212 | F53: =VLOOKUP(A53,[1]Base!$A$5:$B$265, 2, FALSE) -> 1314.47 | G53: =B53/F53 -> 0.04161373 | H53: =Tabla1[[#This Row],[Merval $]]/F53 -> 1792.7612 | I53: =LN(G53/G54) -> -0.0022069383 | J53: =LN(H53/H54) -> 0.0071888674 | K53: =VLOOKUP(Tabla1[[#This Row],[Fecha]],[1]Base!$N$5:$O$263,2,FALSE) -> 823 | O53: Beta | P53: {=INDEX(LINEST(D10:D254,E10:E254),1)} -> 0.87767651 | Q53: {=INDEX(LINEST(I10:I254,J10:J254),1)} -> 0.89453209
A54: 45747 | B54: 54.8 | C54: =VLOOKUP(Tabla1[[#This Row],[Fecha]],[1]Base!$K$5:$L$249,2,FALSE) -> 2338760.8 | D54: =LN(B54/B55) -> -0.025226563 | E54: =LN(C54/C55) -> -0.016875224 | F54: =VLOOKUP(A54,[1]Base!$A$5:$B$265, 2, FALSE) -> 1313.97 | G54: =B54/F54 -> 0.041705671 | H54: =Tabla1[[#This Row],[Merval $]]/F54 -> 1779.9194 | I54: =LN(G54/G55) -> -0.034040223 | J54: =LN(H54/H55) -> -0.025688884 | K54: =VLOOKUP(Tabla1[[#This Row],[Fecha]],[1]Base!$N$5:$O$263,2,FALSE) -> 816
A55: 45744 | B55: 56.2 | C55: =VLOOKUP(Tabla1[[#This Row],[Fecha]],[1]Base!$K$5:$L$249,2,FALSE) -> 2378562.8 | D55: =LN(B55/B56) -> -0.033248907 | E55: =LN(C55/C56) -> -0.013993649 | F55: =VLOOKUP(A55,[1]Base!$A$5:$B$265, 2, FALSE) -> 1302.44 | G55: =B55/F55 -> 0.04314978 | H55: =Tabla1[[#This Row],[Merval $]]/F55 -> 1826.2359 | I55: =LN(G55/G56) -> -0.041072497 | J55: =LN(H55/H56) -> -0.021817239 | K55: =VLOOKUP(Tabla1[[#This Row],[Fecha]],[1]Base!$N$5:$O$263,2,FALSE) -> 797
A56: 45743 | B56: 58.1 | C56: =VLOOKUP(Tabla1[[#This Row],[Fecha]],[1]Base!$K$5:$L$249,2,FALSE) -> 2412081.5 | D56: =LN(B56/B57) -> -0.0068610904 | E56: =LN(C56/C57) -> -0.01149414 | F56: =VLOOKUP(A56,[1]Base!$A$5:$B$265, 2, FALSE) -> 1292.29 | G56: =B56/F56 -> 0.044958949 | H56: =Tabla1[[#This Row],[Merval $]]/F56 -> 1866.5172 | I56: =LN(G56/G57) -> -0.0042798654 | J56: =LN(H56/H57) -> -0.0089129146 | K56: =VLOOKUP(Tabla1[[#This Row],[Fecha]],[1]Base!$N$5:$O$263,2,FALSE) -> 759
A57: 45742 | B57: 58.5 | C57: =VLOOKUP(Tabla1[[#This Row],[Fecha]],[1]Base!$K$5:$L$249,2,FALSE) -> 2439966.2 | D57: =LN(B57/B58) -> -0.020305266 | E57: =LN(C57/C58) -> -0.019366242 | F57: =VLOOKUP(A57,[1]Base!$A$5:$B$265, 2, FALSE) -> 1295.63 | G57: =B57/F57 -> 0.045151779 | H57: =Tabla1[[#This Row],[Merval $]]/F57 -> 1883.2277 | I57: =LN(G57/G58) -> -0.021332321 | J57: =LN(H57/H58) -> -0.020393296 | K57: =VLOOKUP(Tabla1[[#This Row],[Fecha]],[1]Base!$N$5:$O$263,2,FALSE) -> 769
A58: 45741 | B58: 59.7 | C58: =VLOOKUP(Tabla1[[#This Row],[Fecha]],[1]Base!$K$5:$L$249,2,FALSE) -> 2487679.8 | D58: =LN(B58/B59) -> -0.0083403319 | E58: =LN(C58/C59) -> 0.02200418 | F58: =VLOOKUP(A58,[1]Base!$A$5:$B$265, 2, FALSE) -> 1294.3 | G58: =B58/F58 -> 0.046125319 | H58: =Tabla1[[#This Row],[Merval $]]/F58 -> 1922.0272 | I58: =LN(G58/G59) -> -0.013825486 | J58: =LN(H58/H59) -> 0.016519026 | K58: =VLOOKUP(Tabla1[[#This Row],[Fecha]],[1]Base!$N$5:$O$263,2,FALSE) -> 761
A59: 45737 | B59: 60.2 | C59: =VLOOKUP(Tabla1[[#This Row],[Fecha]],[1]Base!$K$5:$L$249,2,FALSE) -> 2433538.2 | D59: =LN(B59/B60) -> 0.037229342 | E59: =LN(C59/C60) -> 0.030014111 | F59: =VLOOKUP(A59,[1]Base!$A$5:$B$265, 2, FALSE) -> 1287.22 | G59: =B59/F59 -> 0.046767452 | H59: =Tabla1[[#This Row],[Merval $]]/F59 -> 1890.5379 | I59: =LN(G59/G60) -> 0.037516742 | J59: =LN(H59/H60) -> 0.030301511 | K59: =VLOOKUP(Tabla1[[#This Row],[Fecha]],[1]Base!$N$5:$O$263,2,FALSE) -> 769
A60: 45736 | B60: 58 | C60: =VLOOKUP(Tabla1[[#This Row],[Fecha]],[1]Base!$K$5:$L$249,2,FALSE) -> 2361583 | D60: =LN(B60/B61) -> -0.032233495 | E60: =LN(C60/C61) -> -0.012810221 | F60: =VLOOKUP(A60,[1]Base!$A$5:$B$265, 2, FALSE) -> 1287.59 | G60: =B60/F60 -> 0.045045395 | H60: =Tabla1[[#This Row],[Merval $]]/F60 -> 1834.111 | I60: =LN(G60/G61) -> -0.033173677 | J60: =LN(H60/H61) -> -0.013750403 | K60: =VLOOKUP(Tabla1[[#This Row],[Fecha]],[1]Base!$N$5:$O$263,2,FALSE) -> 762
A61: 45735 | B61: 59.9 | C61: =VLOOKUP(Tabla1[[#This Row],[Fecha]],[1]Base!$K$5:$L$249,2,FALSE) -> 2392030 | D61: =LN(B61/B62) -> 0.013445581 | E61: =LN(C61/C62) -> 0.044229192 | F61: =VLOOKUP(A61,[1]Base!$A$5:$B$265, 2, FALSE) -> 1286.38 | G61: =B61/F61 -> 0.046564779 | H61: =Tabla1[[#This Row],[Merval $]]/F61 -> 1859.505 | I61: =LN(G61/G62) -> 0.023454559 | J61: =LN(H61/H62) -> 0.054238171 | K61: =VLOOKUP(Tabla1[[#This Row],[Fecha]],[1]Base!$N$5:$O$263,2,FALSE) -> 777
A62: 45734 | B62: 59.1 | C62: =VLOOKUP(Tabla1[[#This Row],[Fecha]],[1]Base!$K$5:$L$249,2,FALSE) -> 2288538 | D62: =LN(B62/B63) -> -0.03164294 | E62: =LN(C62/C63) -> -0.024928778 | F62: =VLOOKUP(A62,[1]Base!$A$5:$B$265, 2, FALSE) -> 1299.32 | G62: =B62/F62 -> 0.045485331 | H62: =Tabla1[[#This Row],[Merval $]]/F62 -> 1761.3352 | I62: =LN(G62/G63) -> -0.06986855 | J62: =LN(H62/H63) -> -0.063154388 | K62: =VLOOKUP(Tabla1[[#This Row],[Fecha]],[1]Base!$N$5:$O$263,2,FALSE) -> 787
A63: 45733 | B63: 61 | C63: =VLOOKUP(Tabla1[[#This Row],[Fecha]],[1]Base!$K$5:$L$249,2,FALSE) -> 2346305.5 | D63: =LN(B63/B64) -> 0.028264558 | E63: =LN(C63/C64) -> 0.004583957 | F63: =VLOOKUP(A63,[1]Base!$A$5:$B$265, 2, FALSE) -> 1250.59 | G63: =B63/F63 -> 0.048776977 | H63: =Tabla1[[#This Row],[Merval $]]/F63 -> 1876.1589 | I63: =LN(G63/G64) -> 0.017968571 | J63: =LN(H63/H64) -> -0.0057120305 | K63: =VLOOKUP(Tabla1[[#This Row],[Fecha]],[1]Base!$N$5:$O$263,2,FALSE) -> 750
A64: 45730 | B64: 59.3 | C64: =VLOOKUP(Tabla1[[#This Row],[Fecha]],[1]Base!$K$5:$L$249,2,FALSE) -> 2335574.8 | D64: =LN(B64/B65) -> 0.048368668 | E64: =LN(C64/C65) -> 0.04527932 | F64: =VLOOKUP(A64,[1]Base!$A$5:$B$265, 2, FALSE) -> 1237.78 | G64: =B64/F64 -> 0.047908352 | H64: =Tabla1[[#This Row],[Merval $]]/F64 -> 1886.9062 | I64: =LN(G64/G65) -> 0.044945407 | J64: =LN(H64/H65) -> 0.041856059 | K64: =VLOOKUP(Tabla1[[#This Row],[Fecha]],[1]Base!$N$5:$O$263,2,FALSE) -> 737
A65: 45729 | B65: 56.5 | C65: =VLOOKUP(Tabla1[[#This Row],[Fecha]],[1]Base!$K$5:$L$249,2,FALSE) -> 2232180 | D65: =LN(B65/B66) -> -0.0035335726 | E65: =LN(C65/C66) -> -0.018094031 | F65: =VLOOKUP(A65,[1]Base!$A$5:$B$265, 2, FALSE) -> 1233.55 | G65: =B65/F65 -> 0.045802764 | H65: =Tabla1[[#This Row],[Merval $]]/F65 -> 1809.5578 | I65: =LN(G65/G66) -> -0.0069523238 | J65: =LN(H65/H66) -> -0.021512783 | K65: =VLOOKUP(Tabla1[[#This Row],[Fecha]],[1]Base!$N$5:$O$263,2,FALSE) -> 748
...

Sheet 2) Research
K22: Facturacion | N22: Precio promedio 2024 | O22: 112183500
K23: Mercado | L23: 773617700000 | N23: Precio Agrometal | O23: ='6) Proyecciones'!F15 -> 1.9967982e+08
K24: AGRO | L24: 84924515513 | N24: Sobre precio | O24: =O23/O22 -> 1.7799393
K25: Participación | L25: =L24/L23 -> 0.10977582
K28: Empresa | L28: Producción agrícola | M28: Participación
K29: Mercado | L29: 6896
K30: John Deere | L30: 1634.352 | M30: =L30/$L$29 -> 0.237
K31: New Holland | L31: 724.08 | M31: =L31/$L$29 -> 0.105
K32: Case IH | L32: 799.936 | M32: =L32/$L$29 -> 0.116
K33: Crucianelli | L33: 393.072 | M33: =L33/$L$29 -> 0.057
K34: Pauny | L34: 413.76 | M34: =L34/$L$29 -> 0.06
K35: Metlflor | L35: 234.464 | M35: =L35/$L$29 -> 0.034
K36: Agrometal | L36: 323 | M36: =L36/$L$29 -> 0.046838747
K37: Pla | L37: 199.984 | M37: =L37/$L$29 -> 0.029
K38: Massey Ferguson | L38: 199.984 | M38: =L38/$L$29 -> 0.029
K39: Mainero | L39: 179.296 | M39: =L39/$L$29 -> 0.026
K41: Fuente: elaboración propia en base a RNM e INDEC

Sheet 3) Macro
B6: IPC mensual base 2016 | C6: Inflación mensual | D6: TC MEP | E6: EMAE base 2004 | F6: M/M% | H6: Columna1 | I6: Inflación anual | J6: TC MEP | K6: PBI
A7: 43831 | B7: 289.8299 | E7: 140.70852 | H7: 2020 | I7: =[1]Base!V16 -> 0.361 | J7: 122.63622 | K7: =Base!$AJ14 -> -0.099
A8: 43862 | B8: 295.666 | C8: =B8/B7-1 -> 0.020136294 | E8: 138.88807 | F8: =E8/E7-1 -> -0.012937698 | H8: 2021 | I8: =[1]Base!V28 -> 0.50941634 | J8: 164.48068 | K8: =Base!$AJ15 -> 0.10441812
A9: 43891 | B9: 305.5515 | C9: =B9/B8-1 -> 0.033434686 | D9: 87.930833 | E9: 125.48317 | F9: =E9/E8-1 -> -0.096515867 | H9: 2022 | I9: =[1]Base!V40 -> 0.94793182 | J9: 250.58223 | K9: =Base!$AJ16 -> 0.052698797
A10: 43922 | B10: 310.1243 | C10: =B10/B9-1 -> 0.014965726 | D10: 100.62767 | E10: 106.10837 | F10: =E10/E9-1 -> -0.15440158 | H10: 2023 | I10: =[1]Base!V52 -> 2.1140764 | J10: 573.54615 | K10: =Base!$AJ17 -> -0.016110016
A11: 43952 | B11: 314.9087 | C11: =B11/B10-1 -> 0.015427363 | D11: 113.14742 | E11: 117.63514 | F11: =E11/E10-1 -> 0.10863201 | H11: 2024 | I11: =[1]Base!V64 -> 1.1776363 | J11: 1163.4084 | K11: =Base!$AJ18 -> -0.017191052
A12: 43983 | B12: 321.9738 | C12: =B12/B11-1 -> 0.022435392 | D12: 106.66552 | E12: 124.84622 | F12: =E12/E11-1 -> 0.061300389 | H12: 2025 | I12: 0.359 | J12: 1300 | K12: =Base!$AJ19 -> 0.055
A13: 44013 | B13: 328.2014 | C13: =B13/B12-1 -> 0.019341946 | D13: 112.09 | E13: 126.19018 | F13: =E13/E12-1 -> 0.010764958 | H13: 2026E | I13: 0.145 | J13: ='6) Proyecciones'!H7 -> 1715.4565 | K13: =Base!$AJ20 -> 0.045
A14: 44044 | B14: 337.0632 | C14: =B14/B13-1 -> 0.027001104 | D14: 124.42871 | E14: 129.01079 | F14: =E14/E13-1 -> 0.022352027 | H14: 2027E | I14: 0.094 | J14: ='6) Proyecciones'!I7 -> 1838.6132 | K14: =Base!$AJ21 -> 0.04
A15: 44075 | B15: 346.6207 | C15: =B15/B14-1 -> 0.028355216 | D15: 126.99267 | E15: 130.82176 | F15: =E15/E14-1 -> 0.014037415 | H15: 2028E | I15: 0.075 | J15: ='6) Proyecciones'!J7 -> 1933.0625 | K15: =Base!$AJ22 -> 0.032
A16: 44105 | B16: 359.657 | C16: =B16/B15-1 -> 0.037609698 | D16: 147.92129 | E16: 133.64962 | F16: =E16/E15-1 -> 0.021616074 | H16: 2029E | I16: 0.075 | J16: ='6) Proyecciones'!K7 -> 2033.3094 | K16: =Base!$AJ23 -> 0.031
A17: 44136 | B17: 371.0211 | C17: =B17/B16-1 -> 0.031597049 | D17: 143.776 | E17: 134.91069 | F17: =E17/E16-1 -> 0.0094356794 | H17: 2030E | I17: 0.075 | J17: ='6) Proyecciones'!L7 -> 2138.7549 | K17: =Base!$AJ24 -> 0.03
A18: 44166 | B18: 385.8826 | C18: =B18/B17-1 -> 0.040055673 | D18: 140.59323 | E18: 136.76102 | F18: =E18/E17-1 -> 0.013715173
A19: 44197 | B19: 401.5071 | C19: =B19/B18-1 -> 0.040490294 | D19: 145.18355 | E19: 139.73714 | F19: =E19/E18-1 -> 0.021761532
A20: 44228 | B20: 415.8595 | C20: =B20/B19-1 -> 0.035746317 | D20: 145.555 | E20: 137.25835 | F20: =E20/E19-1 -> -0.017739016
A21: 44256 | B21: 435.8657 | C21: =B21/B20-1 -> 0.048108075 | D21: 143.5729 | E21: 140.61116 | F21: =E21/E20-1 -> 0.024427004
A22: 44287 | B22: 453.6503 | C22: =B22/B21-1 -> 0.040802935 | D22: 145.49033 | E22: 139.63372 | F22: =E22/E21-1 -> -0.0069513487
A23: 44317 | B23: 468.725 | C23: =B23/B22-1 -> 0.033229781 | D23: 155.76968 | E23: 139.10437 | F23: =E23/E22-1 -> -0.0037910015
A24: 44348 | B24: 483.6049 | C24: =B24/B23-1 -> 0.03174548 | D24: 160.68433 | E24: 141.74208 | F24: =E24/E23-1 -> 0.018962146
A25: 44378 | B25: 498.0987 | C25: =B25/B24-1 -> 0.029970333 | D25: 166.38548 | E25: 141.54961 | F25: =E25/E24-1 -> -0.0013579115
A26: 44409 | B26: 510.3942 | C26: =B26/B25-1 -> 0.024684867 | D26: 169.62581 | E26: 143.43631 | F26: =E26/E25-1 -> 0.013328855
A27: 44440 | B27: 528.4968 | C27: =B27/B26-1 -> 0.03546788 | D27: 172.06467 | E27: 144.04418 | F27: =E27/E26-1 -> 0.0042379518
A28: 44470 | B28: 547.0802 | C28: =B28/B27-1 -> 0.035162748 | D28: 177.66645 | E28: 143.53112 | F28: =E28/E27-1 -> -0.003561816
A29: 44501 | B29: 560.9184 | C29: =B29/B28-1 -> 0.025294646 | D29: 192.11067 | E29: 145.86834 | F29: =E29/E28-1 -> 0.016283706
... A56: 45323 | B56: 4825.7881 | C56: =B56/B55-1 -> 0.13240676 | D56: 1124.1981 | E56: 142.72178 | F56: =E56/E55-1 -> -0.0036641006
A57: 45352 | B57: 5357.0929 | C57: =B57/B56-1 -> 0.110097 | D57: 1019.4886 | E57: 141.63784 | F57: =E57/E56-1 -> -0.0075948112 | G57: EMAE interanual
A58: 45383 | B58: 5830.2271 | C58: =B58/B57-1 -> 0.088319208 | D58: 1014.2714 | E58: 139.89994 | F58: =E58/E57-1 -> -0.012269973 | G58: =E58/$E$57-1 -> -0.012269973
A59: 45413 | B59: 6073.7165 | C59: =B59/B58-1 -> 0.041763279 | D59: 1114.0826 | E59: 141.22741 | F59: =E59/E58-1 -> 0.0094886652 | G59: =E59/$E$57-1 -> -0.0028977335
A60: 45444 | B60: 6351.7145 | C60: =B60/B59-1 -> 0.045770658 | D60: 1281.3585 | E60: 141.59164 | F60: =E60/E59-1 -> 0.0025790429 | G60: =E60/$E$57-1 -> -0.00032616397
A61: 45474 | B61: 6607.7479 | C61: =B61/B60-1 -> 0.040309337 | D61: 1349.1143 | E61: 145.52645 | F61: =E61/E60-1 -> 0.027789836 | G61: =E61/$E$57-1 -> 0.027454608
A62: 45505 | B62: 6883.4412 | C62: =B62/B61-1 -> 0.041722733 | D62: 1295.3645 | E62: 146.97579 | F62: =E62/E61-1 -> 0.0099592976 | G62: =E62/$E$57-1 -> 0.037687335
A63: 45536 | B63: 7122.2421 | C63: =B63/B62-1 -> 0.034692081 | D63: 1228.551 | E63: 146.96724 | F63: =E63/E62-1 -> -5.8181092e-05 | G63: =E63/$E$57-1 -> 0.037626961
A64: 45566 | B64: 7313.9542 | C64: =B64/B63-1 -> 0.02691738 | D64: 1159.8122 | E64: 147.57859 | F64: =E64/E63-1 -> 0.0041597753 | G64: =E64/$E$57-1 -> 0.041943256
A65: 45597 | B65: 7491.4314 | C65: =B65/B64-1 -> 0.024265561 | D65: 1106.0081 | E65: 148.88807 | F65: =E65/E64-1 -> 0.0088731002 | G65: =E65/$E$57-1 -> 0.051188523
A66: 45627 | B66: 7694.0075 | C66: =B66/B65-1 -> 0.027041041 | D66: 1111.2664 | E66: 150.68166 | F66: =E66/E65-1 -> 0.01204659 | G66: =E66/$E$57-1 -> 0.06385176
A67: 45658 | B67: 7864.1257 | C67: =B67/B66-1 -> 0.02211048 | D67: 1164.7291 | E67: 151.46936 | F67: =E67/E66-1 -> 0.0052275413 | G67: =E67/$E$57-1 -> 0.069413089
A68: 45689 | B68: 8052.9927 | C68: =B68/B67-1 -> 0.024016274 | D68: 1198.356 | E68: 152.59215 | F68: =E68/E67-1 -> 0.0074126791 | G68: =E68/$E$57-1 -> 0.077340306
A69: 45717 | B69: 8353.3158 | C69: =B69/B68-1 -> 0.037293353 | D69: 1262.3324 | E69: 149.89801 | F69: =E69/E68-1 -> -0.017655814 | G69: =E69/$E$57-1 -> 0.058318986
A70: 45748 | B70: 8585.6078 | C70: =B70/B69-1 -> 0.027808358 | D70: 1245.3718 | F70: =E70/E69-1 -> -1
A71: 45778 | D71: 1159.7591 | F71: =E71/E70-1 -> #DIV/0!
...

Sheet 4) Financial Statements
A1: FINANCIAL STATEMENTS | B1: 2020 | C1: 2021 | D1: 2022 | E1: 2023 | F1: 2024
A2: Dólar Promedio | B2: ='3) Macro'!J7 -> 122.63622 | C2: ='3) Macro'!J8 -> 164.48068 | D2: ='3) Macro'!J9 -> 250.58223 | E2: ='3) Macro'!J10 -> 573.54615 | F2: ='3) Macro'!J11 -> 1163.4084
A5: PESOS ($)
A6: Income Statement
A7: Revenues | B7: 3640221476 | C7: 7933240381 | D7: 14658891753 | E7: 22474661058 | F7: 63697863191
A8: Operating Costs | B8: =-2236831045 -> -2236831045 | C8: =-4721883737 -> -4721883737 | D8: =-8678223967 -> -8678223967 | E8: =-15735402981 -> -15735402981 | F8: =-44705660747 -> -44705660747
A9: Gross Income | B9: =B7+B8 -> 1403390431 | C9: =C7+C8 -> 3211356644 | D9: =D7+D8 -> 5980667786 | E9: =E7+E8 -> 6739258077 | F9: =F7+F8 -> 18992202444
A10: SG&A | B10: =-SUM(B11:B12) -> -386635412 | C10: =-SUM(C11:C12) -> -754386815 | D10: =-SUM(D11:D12) -> -1621608974 | E10: =-SUM(E11:E12) -> -4189118364 | F10: =-SUM(F11:F12) -> -9936762045
A11: Gasto de comercialización | B11: =183116829 -> 183116829 | C11: 358109025 | D11: =796614304 -> 796614304 | E11: =1824457306 -> 1824457306 | F11: 4852573989
A12: Gasto de administración | B12: 203518583 | C12: 396277790 | D12: =824994670 -> 824994670 | E12: =2364661058 -> 2364661058 | F12: 5084188056
A13: Others | B13: =SUM(B14:B15) -> -183984112 | C13: =SUM(C14:C15) -> -516085800 | D13: =SUM(D14:D15) -> -2491222223 | E13: =SUM(E14:E15) -> -4189674224 | F13: =SUM(F14:F15) -> -3049579706
A14: Resultado por exposición a los cambios en el poder adquisitivo de la moneda | B14: =-110905318 -> -110905318 | C14: =-524480520 -> -524480520 | D14: =-2505563439 -> -2505563439 | E14: =-4282932805 -> -4282932805 | F14: =-3060635304 -> -3060635304
A15: Ingresos y egresos netos | B15: =-73078794 -> -73078794 | C15: 8394720 | D15: =14341216 -> 14341216 | E15: 93258581 | F15: 11055598
A16: EBIT | B16: =B9+B10+B13 -> 832770907 | C16: =C9+C10+C13 -> 1940884029 | D16: =D9+D10+D13 -> 1867836589 | E16: =E9+E10+E13 -> -1639534511 | F16: =F9+F10+F13 -> 6005860693
A17: Net Financial Results | B17: =SUM(B18:B19) -> -387280955 | C17: =SUM(C18:C19) -> -201465816 | D17: =SUM(D18:D19) -> -496556473 | E17: =SUM(E18:E19) -> -2213503083 | F17: =SUM(F18:F19) -> -295881714
A18: Ingresos financieros | B18: 85862010 | C18: 300420734 | D18: =725355208 -> 725355208 | E18: 2567148681 | F18: 2678678603
A19: Egresos financieros | B19: =-473142965 -> -473142965 | C19: =-501886550 -> -501886550 | D19: =-1221911681 -> -1221911681 | E19: =-4780651764 -> -4780651764 | F19: =-2974560317 -> -2974560317
A20: Earnings Before Taxes | B20: =B16+B17 -> 445489952 | C20: =C16+C17 -> 1739418213 | D20: =D16+D17 -> 1371280116 | E20: =E16+E17 -> -3853037594 | F20: =F16+F17 -> 5709978979
A21: Income Tax | B21: =-143150963 -> -143150963 | C21: =-619392065 -> -619392065 | D21: =-535054471 -> -535054471 | E21: 615553017 | F21: =-3125369576 -> -3125369576
A22: Net Income | B22: =B20+B21 -> 302338989 | C22: =C20+C21 -> 1120026148 | D22: =D20+D21 -> 836225645 | E22: =E20+E21 -> -3237484577 | F22: =F20+F21 -> 2584609403
B24: =B21/B20 -> -0.32133376 | C24: =C21/C20 -> -0.35609151 | D24: =D21/D20 -> -0.39018612 | E24: =E21/E20 -> -0.15975785 | F24: =F21/F20 -> -0.5473522 | G24: =AVERAGE(B24:F24) -> -0.35494429
A25: Balance Sheet
A26: Cash & ST Investments | B26: 588858045 | C26: 1186625716 | D26: 1275948509 | E26: 2458458439 | F26: 7394531088
A27: Receivables | B27: 343644441 | C27: 1013004174 | D27: 1459736354 | E27: 3182055900 | F27: 12851298972
A28: Inventories | B28: 443240255 | C28: 1119818347 | D28: 1890044461 | E28: 4084702777 | F28: 8678279963
A29: Other receivables | B29: 644764271 | C29: 1507979735 | D29: 1839629040 | E29: 2447289605 | F29: 3892334361
A30: Current Assets | B30: =SUM(B26:B29) -> 2020507012 | C30: =SUM(C26:C29) -> 4827427972 | D30: =SUM(D26:D29) -> 6465358364 | E30: =SUM(E26:E29) -> 12172506721 | F30: =SUM(F26:F29) -> 32816444384
A31: Fixed Assets | B31: 757842389 | C31: 1203471344 | D31: 2684795381 | E31: 8428778720 | F31: 18385420430
A32: Other | B32: =SUM(B33:B35) -> 8497777 | C32: =SUM(C33:C35) -> 12538187 | D32: =SUM(D33:D35) -> 23869289 | E32: =SUM(E33:E35) -> 592415966 | F32: =SUM(F33:F35) -> 3261326089
A33: Propiedades de inversión | B33: 8497777 | C33: 12538187 | D33: 23869289 | E33: 72600386 | F33: 154358791
A34: Activo por impuesto diferido | C34: 0 | D34: 0 | E34: 519815580 | F34: 31162108
A35: Créditos por ventas | C35: 0 | D35: 0 | E35: 0 | F35: 3075805190
A36: Non Current Assets | B36: =SUM(B31:B32) -> 766340166 | C36: =SUM(C31:C32) -> 1216009531 | D36: =SUM(D31:D32) -> 2708664670 | E36: =SUM(E31:E32) -> 9021194686 | F36: =SUM(F31:F32) -> 21646746519
A37: Total Assets | B37: =B30+B36 -> 2786847178 | C37: =C30+C36 -> 6043437503 | D37: =D30+D36 -> 9174023034 | E37: =E30+E36 -> 21193701407 | F37: =F30+F36 -> 54463190903
A38: Payables | B38: 378394206 | C38: 421151305 | D38: 914425611 | E38: 663133450 | F38: 5442752288
A39: Loans | B39: 293554093 | C39: 482245050 | D39: 1031754217 | E39: 3665556676 | F39: 6886952651
A40: Remuneraciones y Deudas sociales | B40: 74744081 | C40: 179220183 | D40: 296617720 | E40: 581546869 | F40: 1280599720
A41: Fiscales | B41: 127303502 | C41: 635763012 | D41: 113803295 | E41: 88779717 | F41: 2924936225
A42: Anticipos de Clientes | B42: 514650909 | C42: 1204710440 | D42: 675522485 | E42: 950830550 | F42: 3092212223
A43: Other | B43: 36471143 | C43: 97000000 | D43: 216684944 | E43: 681524392 | F43: 1386572832
...

Sheet 5) Ratios
A5: Indicador | B5: 2020 | C5: 2021 | D5: 2022 | E5: 2023 | F5: 2024
A6: Ratios de liquidez
A7: Liquidez corriente | B7: ='4) Financial Statements'!B$30/'4) Financial Statements'!B$44 -> 1.4177823 | C7: ='4) Financial Statements'!C$30/'4) Financial Statements'!C$44 -> 1.5984385 | D7: ='4) Financial Statements'!D$30/'4) Financial Statements'!D$44 -> 1.9900708 | E7: ='4) Financial Statements'!E$30/'4) Financial Statements'!E$44 -> 1.8355941 | F7: ='4) Financial Statements'!F$30/'4) Financial Statements'!F$44 -> 1.5616448
A8: Liquidez seca | B8: =('4) Financial Statements'!B$30-'4) Financial Statements'!B$28)/'4) Financial Statements'!B$44 -> 1.1067623 | C8: =('4) Financial Statements'!C$30-'4) Financial Statements'!C$28)/'4) Financial Statements'!C$44 -> 1.2276487 | D8: =('4) Financial Statements'!D$30-'4) Financial Statements'!D$28)/'4) Financial Statements'!D$44 -> 1.4083053 | E8: =('4) Financial Statements'!E$30-'4) Financial Statements'!E$28)/'4) Financial Statements'!E$44 -> 1.2196276 | F8: =('4) Financial Statements'!F$30-'4) Financial Statements'!F$28)/'4) Financial Statements'!F$44 -> 1.1486692
A9: Liquidez de CP | B9: =('4) Financial Statements'!B$26+'4) Financial Statements'!B$27)/'4) Financial Statements'!B$44 -> 0.65433356 | C9: =('4) Financial Statements'!C$26+'4) Financial Statements'!C$27)/'4) Financial Statements'!C$44 -> 0.72833257 | D9: =('4) Financial Statements'!D$26+'4) Financial Statements'!D$27)/'4) Financial Statements'!D$44 -> 0.84205796 | E9: =('4) Financial Statements'!E$26+'4) Financial Statements'!E$27)/'4) Financial Statements'!E$44 -> 0.85058034 | F9: =('4) Financial Statements'!F$26+'4) Financial Statements'!F$27)/'4) Financial Statements'!F$44 -> 0.96344366
A10: Capital de Trabajo | B10: ='4) Financial Statements'!B$107-'4) Financial Statements'!B$115 -> 4854920.2 | C10: ='4) Financial Statements'!C$107-'4) Financial Statements'!C$115 -> 10988147 | D10: ='4) Financial Statements'!D$107-'4) Financial Statements'!D$115 -> 12836305 | E10: ='4) Financial Statements'!E$107-'4) Financial Statements'!E$115 -> 9661184.2 | F10: ='4) Financial Statements'!F$107-'4) Financial Statements'!F$115 -> 10144690
A11: Liquidez operativa | B11: =(('4) Financial Statements'!B53+('4) Financial Statements'!B39+'4) Financial Statements'!B45-'4) Financial Statements'!B26))/'4) Financial Statements'!B37) -> 0.33403523 | C11: =(('4) Financial Statements'!C53+('4) Financial Statements'!C39+'4) Financial Statements'!C45-'4) Financial Statements'!C26))/'4) Financial Statements'!C37) -> 0.36481964 | D11: =(('4) Financial Statements'!D53+('4) Financial Statements'!D39+'4) Financial Statements'!D45-'4) Financial Statements'!D26))/'4) Financial Statements'!D37) -> 0.59915267 | E11: =(('4) Financial Statements'!E53+('4) Financial Statements'!E39+'4) Financial Statements'!E45-'4) Financial Statements'!E26))/'4) Financial Statements'!E37) -> 0.74337108 | F11: =(('4) Financial Statements'!F53+('4) Financial Statements'!F39+'4) Financial Statements'!F45-'4) Financial Statements'!F26))/'4) Financial Statements'!F37) -> 0.60484074
A12: Ratios de endeudamiento
A13: Endeudamiento sobre PN | B13: ='4) Financial Statements'!B52/'4) Financial Statements'!B53 -> 1.4423577 | C13: ='4) Financial Statements'!C52/'4) Financial Statements'!C53 -> 1.1390613 | D13: ='4) Financial Statements'!D52/'4) Financial Statements'!D53 -> 0.67682637 | E13: ='4) Financial Statements'!E52/'4) Financial Statements'!E53 -> 0.54762899 | F13: ='4) Financial Statements'!F52/'4) Financial Statements'!F53 -> 0.68977818
A14: Endeudamiento sobre AT | B14: ='4) Financial Statements'!B$52/'4) Financial Statements'!B$37 -> 0.59055956 | C14: ='4) Financial Statements'!C$52/'4) Financial Statements'!C$37 -> 0.53250521 | D14: ='4) Financial Statements'!D$52/'4) Financial Statements'!D$37 -> 0.40363533 | E14: ='4) Financial Statements'!E$52/'4) Financial Statements'!E$37 -> 0.35385031 | F14: ='4) Financial Statements'!F$52/'4) Financial Statements'!F$37 -> 0.40820635
A15: PT/PN | B15: ='4) Financial Statements'!B52/'4) Financial Statements'!B53 -> 1.4423577 | C15: ='4) Financial Statements'!C52/'4) Financial Statements'!C53 -> 1.1390613 | D15: ='4) Financial Statements'!D52/'4) Financial Statements'!D53 -> 0.67682637 | E15: ='4) Financial Statements'!E52/'4) Financial Statements'!E53 -> 0.54762899 | F15: ='4) Financial Statements'!F52/'4) Financial Statements'!F53 -> 0.68977818
A16: Cobertura de intereses | B16: ='4) Financial Statements'!B$16/'4) Financial Statements'!B$19 -> -1.760083 | C16: ='4) Financial Statements'!C$16/'4) Financial Statements'!C$19 -> -3.8671768 | D16: ='4) Financial Statements'!D$16/'4) Financial Statements'!D$19 -> -1.5286183 | E16: ='4) Financial Statements'!E$16/'4) Financial Statements'!E$19 -> 0.34295209 | F16: ='4) Financial Statements'!F$16/'4) Financial Statements'!F$19 -> -2.0190751
A17: Cobertura de intereses (EBITDA) | B17: =('4) Financial Statements'!B$16+'4) Financial Statements'!B$60)/'4) Financial Statements'!B$19 -> -1.8726599 | C17: =('4) Financial Statements'!C$16+'4) Financial Statements'!C$60)/'4) Financial Statements'!C$19 -> -4.0648828 | D17: =('4) Financial Statements'!D$16+'4) Financial Statements'!D$60)/'4) Financial Statements'!D$19 -> -1.7111091 | E17: =('4) Financial Statements'!E$16+'4) Financial Statements'!E$60)/'4) Financial Statements'!E$19 -> 0.1871019 | F17: =('4) Financial Statements'!F$16+'4) Financial Statements'!F$60)/'4) Financial Statements'!F$19 -> -2.534092
A18: Rotacion de credito | B18: ='4) Financial Statements'!B$7/'4) Financial Statements'!B$27 -> 10.592988 | C18: ='4) Financial Statements'!C$7/'4) Financial Statements'!C$27 -> 7.8313995 | D18: ='4) Financial Statements'!D$7/'4) Financial Statements'!D$27 -> 10.04215 | E18: ='4) Financial Statements'!E$7/'4) Financial Statements'!E$27 -> 7.0629372 | F18: ='4) Financial Statements'!F$7/'4) Financial Statements'!F$27 -> 4.9565311
A19: Dias de cobranza | B19: =('4) Financial Statements'!B$27/'4) Financial Statements'!B$7)*360 -> 33.984745 | C19: =('4) Financial Statements'!C$27/'4) Financial Statements'!C$7)*360 -> 45.968795 | D19: =('4) Financial Statements'!D$27/'4) Financial Statements'!D$7)*360 -> 35.848896 | E19: =('4) Financial Statements'!E$27/'4) Financial Statements'!E$7)*360 -> 50.970296 | F19: =('4) Financial Statements'!F$27/'4) Financial Statements'!F$7)*360 -> 72.631442
A20: Rotacion de inventario | B20: =-'4) Financial Statements'!B$8/'4) Financial Statements'!B$28 -> 5.0465431 | C20: =-'4) Financial Statements'!C$8/'4) Financial Statements'!C$28 -> 4.2166515 | D20: =-'4) Financial Statements'!D$8/'4) Financial Statements'!D$28 -> 4.5915449 | E20: =-'4) Financial Statements'!E$8/'4) Financial Statements'!E$28 -> 3.8522761 | F20: =-'4) Financial Statements'!F$8/'4) Financial Statements'!F$28 -> 5.1514426
A21: Dias de venta | B21: =('4) Financial Statements'!B$28/(-'4) Financial Statements'!B$8))*360 -> 71.335961 | C21: =('4) Financial Statements'!C$28/(-'4) Financial Statements'!C$8))*360 -> 85.375801 | D21: =('4) Financial Statements'!D$28/(-'4) Financial Statements'!D$8))*360 -> 78.404983 | E21: =('4) Financial Statements'!E$28/(-'4) Financial Statements'!E$8))*360 -> 93.451245 | F21: =('4) Financial Statements'!F$28/(-'4) Financial Statements'!F$8))*360 -> 69.883338
A22: Dias de pago | B22: =-('4) Financial Statements'!B38/'4) Financial Statements'!B8)*360 -> 60.89951 | C22: =-('4) Financial Statements'!C38/'4) Financial Statements'!C8)*360 -> 32.108895 | D22: =-('4) Financial Statements'!D38/'4) Financial Statements'!D8)*360 -> 37.933248 | E22: =-('4) Financial Statements'!E38/'4) Financial Statements'!E8)*360 -> 15.171397 | F22: =-('4) Financial Statements'!F38/'4) Financial Statements'!F8)*360 -> 43.828696
A23: Apalancamiento financiero | B23: ='4) Financial Statements'!B37/'4) Financial Statements'!B53 -> 2.4423577 | C23: ='4) Financial Statements'!C37/'4) Financial Statements'!C53 -> 2.1390613 | D23: ='4) Financial Statements'!D37/'4) Financial Statements'!D53 -> 1.6768264 | E23: ='4) Financial Statements'!E37/'4) Financial Statements'!E53 -> 1.547629 | F23: ='4) Financial Statements'!F37/'4) Financial Statements'!F53 -> 1.6897782
A24: Rotacion del activo | B24: ='4) Financial Statements'!B$7/'4) Financial Statements'!B$37 -> 1.306215 | C24: ='4) Financial Statements'!C$7/'4) Financial Statements'!C$37 -> 1.3127033 | D24: ='4) Financial Statements'!D$7/'4) Financial Statements'!D$37 -> 1.5978695 | E24: ='4) Financial Statements'!E$7/'4) Financial Statements'!E$37 -> 1.0604406 | F24: ='4) Financial Statements'!F$7/'4) Financial Statements'!F$37 -> 1.169558
A25: Ratios de rentabilidad
A26: Margen neto | B26: ='4) Financial Statements'!B22/'4) Financial Statements'!B7 -> 0.083055108 | C26: ='4) Financial Statements'!C22/'4) Financial Statements'!C7 -> 0.14118142 | D26: ='4) Financial Statements'!D22/'4) Financial Statements'!D7 -> 0.057045625 | E26: ='4) Financial Statements'!E22/'4) Financial Statements'!E7 -> -0.14405043 | F26: ='4) Financial Statements'!F22/'4) Financial Statements'!F7 -> 0.040576077
A27: ROA | B27: ='4) Financial Statements'!B22/'4) Financial Statements'!B37 -> 0.10848783 | C27: ='4) Financial Statements'!C22/'4) Financial Statements'!C37 -> 0.18532932 | D27: ='4) Financial Statements'!D22/'4) Financial Statements'!D37 -> 0.091151466 | E27: ='4) Financial Statements'!E22/'4) Financial Statements'!E37 -> -0.15275692 | F27: ='4) Financial Statements'!F22/'4) Financial Statements'!F37 -> 0.047456077
A28: ROE | B28: ='4) Financial Statements'!B22/'4) Financial Statements'!B53 -> 0.26496607 | C28: ='4) Financial Statements'!C22/'4) Financial Statements'!C53 -> 0.39643077 | D28: ='4) Financial Statements'!D22/'4) Financial Statements'!D53 -> 0.15284518 | E28: ='4) Financial Statements'!E22/'4) Financial Statements'!E53 -> -0.23641104 | F28: ='4) Financial Statements'!F22/'4) Financial Statements'!F53 -> 0.080190244
A29: ROIC | B29: ='4) Financial Statements'!B16*(1-0.35)/('4) Financial Statements'!B53+('4) Financial Statements'!B39+'4) Financial Statements'!B45-'4) Financial Statements'!B26)) -> 0.58147824 | C29: ='4) Financial Statements'!C16*(1-0.35)/('4) Financial Statements'!C53+('4) Financial Statements'!C39+'4) Financial Statements'!C45-'4) Financial Statements'!C26)) -> 0.57220375 | D29: ='4) Financial Statements'!D16*(1-0.35)/('4) Financial Statements'!D53+('4) Financial Statements'!D39+'4) Financial Statements'!D45-'4) Financial Statements'!D26)) -> 0.22087925 | E29: ='4) Financial Statements'!E16*(1-0.35)/('4) Financial Statements'!E53+('4) Financial Statements'!E39+'4) Financial Statements'!E45-'4) Financial Statements'!E26)) -> -0.06764278 | F29: ='4) Financial Statements'!F16*(1-0.35)/('4) Financial Statements'!F53+('4) Financial Statements'!F39+'4) Financial Statements'!F45-'4) Financial Statements'!F26)) -> 0.11850713
A30: Dupont | B30: =B26*B24*B23 -> 0.26496607 | C30: =C26*C24*C23 -> 0.39643077 | D30: =D26*D24*D23 -> 0.15284518 | E30: =E26*E24*E23 -> -0.23641104 | F30: =F26*F24*F23 -> 0.080190244

Sheet 6) Proyecciones
G3: =G7/F7-1 -> 0.31951456 | H3: =H7/G7-1 -> 0.11746341 | I3: =I7/H7-1 -> 0.07179236 | J3: =J7/I7-1 -> 0.051369863 | K3: =K7/J7-1 -> 0.0518591 | L3: =L7/K7-1 -> 0.0518591
A5: Variable | B5: 2020 | C5: 2021 | D5: 2022 | E5: 2023 | F5: 2024 | G5: 2025 | H5: 2026E | I5: 2027E | J5: 2028E | K5: 2029E | L5: 2030E
A6: PBI | B6: ='3) Macro'!$K7 -> -0.099 | C6: ='3) Macro'!$K8 -> 0.10441812 | D6: ='3) Macro'!$K9 -> 0.052698797 | E6: ='3) Macro'!$K10 -> -0.016110016 | F6: ='3) Macro'!$K11 -> -0.017191052 | G6: ='3) Macro'!$K12 -> 0.055 | H6: ='3) Macro'!$K13 -> 0.045 | I6: ='3) Macro'!$K14 -> 0.04 | J6: ='3) Macro'!$K15 -> 0.032 | K6: ='3) Macro'!$K16 -> 0.031 | L6: ='3) Macro'!$K17 -> 0.03
A7: TC (EOP) | B7: ='3) Macro'!$J7 -> 122.63622 | C7: ='3) Macro'!$J8 -> 164.48068 | D7: ='3) Macro'!$J9 -> 250.58223 | E7: ='3) Macro'!$J10 -> 573.54615 | F7: ='3) Macro'!$J11 -> 1163.4084 | G7: =F7*(1+G8)/(1+G10) -> 1535.1344 | H7: =G7*(1+H8)/(1+H10) -> 1715.4565 | I7: =H7*(1+I8)/(1+I10) -> 1838.6132 | J7: =I7*(1+J8)/(1+J10) -> 1933.0625 | K7: =J7*(1+K8)/(1+K10) -> 2033.3094 | L7: =K7*(1+L8)/(1+L10) -> 2138.7549
A8: Inflacion (AVG) | B8: 0.42 | C8: 0.484 | D8: 0.7243 | E8: 1.3348 | F8: 2.1988 | G8: 0.3591 | H8: 0.1454 | I8: 0.0943 | J8: 0.0745 | K8: 0.075 | L8: 0.075
A9: Inflacion (EOP) | B9: ='3) Macro'!$I7 -> 0.361 | C9: ='3) Macro'!$I8 -> 0.50941634 | D9: ='3) Macro'!$I9 -> 0.94793182 | E9: ='3) Macro'!$I10 -> 2.1140764 | F9: ='3) Macro'!$I11 -> 1.1776363 | G9: ='3) Macro'!$I12 -> 0.359 | H9: ='3) Macro'!$I13 -> 0.145 | I9: ='3) Macro'!$I14 -> 0.094 | J9: ='3) Macro'!$I15 -> 0.075 | K9: ='3) Macro'!$I16 -> 0.075 | L9: ='3) Macro'!$I17 -> 0.075
A10: Inflation USA | G10: 0.03 | H10: 0.025 | I10: 0.021 | J10: 0.022 | K10: 0.022 | L10: 0.022
A11: Precios de la industria | F11: ='2) Research'!O22 -> 112183500 | G11: =F11*(1+G8) -> 1.5246859e+08 | H11: =G11*(1+H8) -> 1.7463753e+08 | I11: =H11*(1+I8) -> 1.9110585e+08 | J11: =I11*(1+J8) -> 2.0534323e+08 | K11: =J11*(1+K8) -> 2.2074398e+08 | L11: =K11*(1+L8) -> 2.3729977e+08
A13: Revenue Model | G13: =G14/F14-1 -> 0.33765789 | H13: =H14/G14-1 -> 0.13003488 | I13: =I14/H14-1 -> 0.082510284 | J13: =J14/I14-1 -> 0.059780822 | K13: =K14/J14-1 -> 0.060011008 | L13: =L14/K14-1 -> 0.059748043 | M13: =AVERAGE(G13:L13) -> 0.12162382 | O13: Revenue | P13: =M13 -> 0.12162382
A14: Revenues | B14: =B15*B16 -> 3640221476 | C14: =C15*C16 -> 7933240381 | D14: =D15*D16 -> 14658891753 | E14: =E15*E16 -> 22474661058 | F14: =F15*F16 -> 63697863191 | G14: =G15*G16 -> 8.5205949e+10 | H14: =H15*H16 -> 9.6285694e+10 | I14: =I15*I16 -> 1.0423025e+11 | ... L14: =L15*L16 -> 1.2408602e+11 | O14: Costos operativos | P14: =M17 -> 0.10221334
A15: Price | B15: ='4) Financial Statements'!B7/'6) Proyecciones'!$B16 -> 9239140.8 | C15: ='4) Financial Statements'!C7/'6) Proyecciones'!$C16 -> 16527584 | D15: ='4) Financial Statements'!D7/'6) Proyecciones'!$D16 -> 30038713 | E15: ='4) Financial Statements'!E7/'6) Proyecciones'!$E16 -> 96873539 | F15: ='4) Financial Statements'!$F7/'6) Proyecciones'!$F16 -> 1.9967982e+08 | G15: =F15*(1+G3) -> 2.6348043e+08 | H15: =G15*(1+H3) -> 2.9442974e+08 | I15: =H15*(1+I3) -> 3.1556755e+08 | J15: =I15*(1+J3) -> 3.3177821e+08 | K15: =J15*(1+K3) -> 3.4898393e+08 | L15: =K15*(1+L3) -> 3.6708192e+08 | O15: Gastos adm | P15: =M24 -> 0.05
A16: Q (Cantidad) | B16: 394 | C16: 480 | D16: 488 | E16: 232 | F16: 319 | G16: =F16*(1+G6*$M$16) -> 323.38625 | H16: =G16*(1+H6*$M$16) -> 327.02435 | I16: =H16*(1+I6*$M$16) -> 330.29459 | J16: =I16*(1+J6*$M$16) -> 332.93695 | K16: =J16*(1+K6*$M$16) -> 335.51721 | L16: =K16*(1+L6*$M$16) -> 338.03359 | M16: =1/4 -> 0.25 | O16: Depreciaciones | P16: =M31 -> 0.047210614
